Workbook
Name jordan: [1]selections!$K$92:$K$108
Name Regions: Selections!$C$2:$C$7
Name Score: Selections!$A$2:$A$5
Name Text1: 'Form Форма'!$I$10
Name Text10: 'Form Форма'!$I$28
Name Text11: 'Form Форма'!$I$30
Name Text12: 'Form Форма'!$I$36
Name Text13: 'Form Форма'!$I$38
Name Text14: 'Form Форма'!$I$40
Name Text15: 'Form Форма'!$I$42
Name Text16: 'Form Форма'!$I$44
Name Text17: 'Form Форма'!$I$48
Name Text18: 'Form Форма'!$I$50
Name Text19: 'Form Форма'!$I$52
Name Text20: 'Form Форма'!$I$54
Name Text21: 'Form Форма'!$I$60
Name Text22: 'Form Форма'!$I$62
Name Text23: 'Form Форма'!$I$64
Name Text24: 'Form Форма'!$I$66
Name Text25: 'Form Форма'!$I$72
Name Text26: 'Form Форма'!$I$74
Name Text27: 'Form Форма'!$I$76
Name Text28: 'Form Форма'!$A$3
Name Text29: 'Form Форма'!$F$3
Name Text30: 'Form Форма'!$I$3
Name Text4: 'Form Форма'!$I$16
Name Text5: 'Form Форма'!$I$18
Name Text6: 'Form Форма'!$I$20
Name Text7: 'Form Форма'!$I$22
Name Text8: 'Form Форма'!$I$24
Name Text9: 'Form Форма'!$I$26

Sheet Form  Форма
B1: Masters Review of Operations Management System / Проверка капитаном системы управления операционной деятельностью | I1: BL_FRM-VSL-12-1303-001
I2: File 12 / Папка 12
I3: Retention 3Y / Срок хранения 3 года
A5: Master Капитан: | C5: Region Регион: | E5: Vessel Судно: | I5: Date Дата:
A7: Elements / Разделы | D7: Required Practices / Требуемые навыки | F7: Effectiveness / Эффективность | I7: Recommendations for Improvement / Рекомендации по улучшению
A8: Mark each section as 3 – Effective, 2 – Some improvement required 1- Not effective. Remarks are required for scores of 2 or 1 / Отметить каждый раздел как: 3 – Эффективно, 2 – Нуждается в некотором улучшении 1- Неэффективно. Для баллов 2 и 1 требуются замечания
A10: SHE-Q Policies Responsibility and Authority [Element 01] / Ответственность и полномочия политики ОТ, ТБ, ООС и КК [Раздел 01] | B10: • Policies implemented and maintained at all levels of vessel and shore organisation / Политики внедрены и поддерживаются на всех уровнях судовой и береговой организаций | F10: select | G10: =IF(F10=3, "Effective", IF(F10=2, "Some improvement required", IF(F10=1, "Not Effective", IF(F10="select", "your choice")))) -> your choice
B12: • Policies posted in public position / Политики вывешены для всеобщего обозрения | F12: select | G12: =IF(F12=3, "Effective", IF(F12=2, "Some improvement required", IF(F12=1, "Not Effective", IF(F12="select", "your choice")))) -> your choice
B14: • Designated Person Ashore providing link between vessel and shore operation ensuring safe operations / Назначенное лицо Компании обеспечивает связь между судном и береговой организацией для обеспечения безопасных операций | F14: select | G14: =IF(F14=3, "Effective", IF(F14=2, "Some improvement required", IF(F14=1, "Not Effective", IF(F14="select", "your choice")))) -> your choice
B16: • Designated Person Ashore monitoring safety and pollution prevention to ensure adequate resources. / Назначенное лицо Компании контролирует безопасность и предотвращение загрязнения для обеспечения адекватных ресурсов. | F16: select | G16: =IF(F16=3, "Effective", IF(F16=2, "Some improvement required", IF(F16=1, "Not Effective", IF(F16="select", "your choice")))) -> your choice
B18: • Designated Person Ashore and Company Security Officer contact details posted in public position / Контактные данные назначенного лица Компании и руководителя по безопасности Компании вывешены для всеобщего обозрения | F18: select | G18: =IF(F18=3, "Effective", IF(F18=2, "Some improvement required", IF(F18=1, "Not Effective", IF(F18="select", "your choice")))) -> your choice
B20: • Master’s responsibility and authority clearly defined in SLIMS / Ответственность и полномочия капитана четко определены в SLIMS | F20: select | G20: =IF(F20=3, "Effective", IF(F20=2, "Some improvement required", IF(F20=1, "Not Effective", IF(F20="select", "your choice")))) -> your choice
B22: • Master is implementing SHE-Q Policies on board / Капитан реализует политики ОТ, ТБ, ООС и КК на борту | F22: select | G22: =IF(F22=3, "Effective", IF(F22=2, "Some improvement required", IF(F22=1, "Not Effective", IF(F22="select", "your choice")))) -> your choice
B24: • Master reviews SLIMS and reports on effectiveness to management / Капитан проводит обзор SLIMS и отчитывается перед руководством в части эффективности | F24: select | G24: =IF(F24=3, "Effective", IF(F24=2, "Some improvement required", IF(F24=1, "Not Effective", IF(F24="select", "your choice")))) -> your choice
A26: Resources and Personnel [Element 2+3] / Ресурсы и персонал [Раздел 2+3] | B26: • Vessel personnel appointed as qualified, certificated and medically fit / Назначается квалифицированный, сертифицированный и пригодный по медицинским показаниям персонал | F26: select | G26: =IF(F26=3, "Effective", IF(F26=2, "Some improvement required", IF(F26=1, "Not Effective", IF(F26="select", "your choice")))) -> your choice
B28: • Vessel induction and familiarisation for new personnel conducted and documented / Проводится и документально оформляется инструктаж и ознакомление с судном нового персонала | F28: select | G28: =IF(F28=3, "Effective", IF(F28=2, "Some improvement required", IF(F28=1, "Not Effective", IF(F28="select", "your choice")))) -> your choice
B30: • Vessel personnel training requirements identified and completed or notified to Regional Office / Требования к обучению судового персонала определены и выполняются или сообщаются в региональный офис | F30: select | G30: =IF(F30=3, "Effective", IF(F30=2, "Some improvement required", IF(F30=1, "Not Effective", IF(F30="select", "your choice")))) -> your choice
B32: Masters Review of Operations Management System / Проверка капитаном системы управления операционной деятельностью | I32: FRM-VSL-12-1303-001
I33: File 12 / Папка 12
I34: Retention 3Y / Срок хранения 3 года
A36: Documentation [Element 1] / Документация [Раздел 1] | B36: • Vessel SLIMS Manuals are current / Судовые руководства по SLIMS поддерживаются на актуальном уровне | F36: select | G36: =IF(F36=3, "Effective", IF(F36=2, "Some improvement required", IF(F36=1, "Not Effective", IF(F36="select", "your choice")))) -> your choice
B38: • Confirm that obsolete manuals and procedures are promptly removed and destroyed / Подтвердите, что устаревшие руководства и процедуры в оперативном порядке изымаются и уничтожаются | F38: select | G38: =IF(F38=3, "Effective", IF(F38=2, "Some improvement required", IF(F38=1, "Not Effective", IF(F38="select", "your choice")))) -> your choice
A40: Vessel Operations [Element 5,6, 7 +9] / Эксплуатация судна [Разделы 5,6, 7 +9] | B40: • Marine Operations procedures reviewed to ensure key operations concerning vessel safety and pollution prevention are satisfactory / Проводится обзор процедур по морским операциям для обеспечения ключевых работ с учетом безопасности судна и предотвращения загрязнения окружающей среды | F40: select | G40: =IF(F40=3, "Effective", IF(F40=2, "Some improvement required", IF(F40=1, "Not Effective", IF(F40="select", "your choice")))) -> your choice
B42: • Key Marine Operations procedures are risk assessed. / Выполняется оценка рисков по процедурам ключевых морских операций. | F42: select | G42: =IF(F42=3, "Effective", IF(F42=2, "Some improvement required", IF(F42=1, "Not Effective", IF(F42="select", "your choice")))) -> your choice
B44: • Safety, Health and Environmental procedures reviewed to ensure safe vessel operations and environmental protection / Осуществляется обзор процедур по технике безопасности, охране труда и окружающей среды для обеспечения безопасных судовых операций и защиты окружающей среды | F44: select | G44: =IF(F44=3, "Effective", IF(F44=2, "Some improvement required", IF(F44=1, "Not Effective", IF(F44="select", "your choice")))) -> your choice
B46: • Management Of Change is understood, used and implemented / Процесс управления изменениями принят к сведению, используется и осуществляется | F46: select | G46: =IF(F46=3, "Effective", IF(F46=2, "Some improvement required", IF(F46=1, "Not Effective", IF(F46="select", "your choice")))) -> your choice
A48: Engineering Repair and Maintenance [Element 4] / Ремонт и техобслуживание [Раздел 4] | B48: • Vessel Engineering procedures reviewed to ensure that preventative maintenance, repairs and engineering operations are carried out in a planned, safe, and timely manner / Проводится обзор инженерно-технических процедур, чтобы обеспечить выполнение профилактического техобслуживания, ремонта в плановом, безопасном и своевременном порядке | F48: select | G48: =IF(F48=3, "Effective", IF(F48=2, "Some improvement required", IF(F48=1, "Not Effective", IF(F48="select", "your choice")))) -> your choice
B50: • Engineering inspections performed in accordance with PMS / Технические проверки выполняются согласно системе планового техобслуживания | F50: select | G50: =IF(F50=3, "Effective", IF(F50=2, "Some improvement required", IF(F50=1, "Not Effective", IF(F50="select", "your choice")))) -> your choice
A52: Emergency Preparedness and Response [Element 11] / Подготовленность и реагирование на аварийные ситуации [Раздел 11] | B52: • Vessel Emergency Response Manual reviewed to ensure that potential vessel emergency situations are adequately addressed / contacts current / Проводится обзор судового руководства по аварийному реагированию для обеспечения адекватного урегулирования потенциальных аварийных ситуаций / контакты поддерживаются на актуальном уровне | F52: select | G52: =IF(F52=3, "Effective", IF(F52=2, "Some improvement required", IF(F52=1, "Not Effective", IF(F52="select", "your choice")))) -> your choice
B54: • Emergency drills and exercises are conducted and documented / Проводятся и документально оформляются учения и УТЗ по реагированию на аварийные ситуации | F54: select | G54: =IF(F54=3, "Effective", IF(F54=2, "Some improvement required", IF(F54=1, "Not Effective", IF(F54="select", "your choice")))) -> your choice
B56: Masters Review of Operations Management System / Проверка капитаном системы управления оперативной деятельностью | I56: FRM-VSL-12-1303-001
I57: File 12 / Папка 12
I58: Retention 3Y / Срок хранения 3 года
A60: Incident Investigation, Non-Conformances and Corrective Actions [Element 8 + 12] / Расследование происшествий, несоответствий и корректирующие действия [Раздел 8 + 12] | B60: • Incidents are investigated to determine root causes and corrective actions / Происшествия расследуются для определения коренных причин и корректирующих действий | F60: select | G60: =IF(F60=3, "Effective", IF(F60=2, "Some improvement required", IF(F60=1, "Not Effective", IF(F60="select", "your choice")))) -> your choice
B62: • Incident investigation findings are distributed to vessel personnel as lessons learned / safety flashes / Выполняется рассылка итогов расследования происшествий судовому персоналу в форме извлеченных уроков / бюллетеней по ТБ | F62: select | G62: =IF(F62=3, "Effective", IF(F62=2, "Some improvement required", IF(F62=1, "Not Effective", IF(F62="select", "your choice")))) -> your choice
B64: • Non-conformances and recommendations for corrective actions are reported to management / Несоответствия и рекомендации по корректирующим действиям докладываются руководству | F64: select | G64: =IF(F64=3, "Effective", IF(F64=2, "Some improvement required", IF(F64=1, "Not Effective", IF(F64="select", "your choice")))) -> your choice
B66: • Corrective actions are closed out / Корректирующие действия выполняются полностью | F66: select | G66: =IF(F66=3, "Effective", IF(F66=2, "Some improvement required", IF(F66=1, "Not Effective", IF(F66="select", "your choice")))) -> your choice
A68: Environmental Protection [Element 10] / Охрана окружающей среды [Раздел 10] | B68: • All incidents with a (possible) environmental impact are reported./ Все происшествия с (возможным) влиянием на окружающую среду докладываются. | F68: select | G68: =IF(F68=3, "Effective", IF(F68=2, "Some improvement required", IF(F68=1, "Not Effective", IF(F68="select", "your choice")))) -> your choice
B70: • Environmental protection is understood / Имеется понимание защиты окружающей среды | G70: =IF(F70=3, "Effective", IF(F70=2, "Some improvement required", IF(F70=1, "Not Effective", IF(F70="select", "your choice")))) -> FALSE
B71: • Environmental parameters are reported to management / Экологические параметры докладываются руководству
...

Sheet Selections
A1: Score | B1: Description | C1: Regions
A2: 3 | B2: Effective | C2: Africa
A3: 2 | B3: Some improvement required | C3: Australia
A4: 1 | B4: Not effective | C4: Europe
A5: select | C5: Nigeria
C6: MEIS
C7: RESA

Sheet data  данные
B2: ='Form Форма'!F5 -> 0 | D2: Copy B2:B65 to the Central Statistics form / Скопировать B2:B65 в форму основной статистики
B3: ='Form Форма'!D5 -> 0
B4: ='Form Форма'!J5 -> 0
B5: ='Form Форма'!B5 -> 0
B6: ='Form Форма'!F10 -> select
B7: ='Form Форма'!F12 -> select
B8: ='Form Форма'!F14 -> select
B9: ='Form Форма'!F16 -> select
B10: ='Form Форма'!F18 -> select
B11: ='Form Форма'!F20 -> select
B12: ='Form Форма'!F22 -> select
B13: ='Form Форма'!F24 -> select
B14: ='Form Форма'!F26 -> select
B15: ='Form Форма'!F28 -> select
B16: ='Form Форма'!F30 -> select
B17: ='Form Форма'!F36 -> select
B18: ='Form Форма'!F38 -> select
B19: ='Form Форма'!F40 -> select
B20: ='Form Форма'!F42 -> select
B21: ='Form Форма'!F44 -> select
B22: ='Form Форма'!F46 -> select
B23: ='Form Форма'!F48 -> select
B24: ='Form Форма'!F50 -> select
B25: ='Form Форма'!F52 -> select
B26: ='Form Форма'!F54 -> select
B27: ='Form Форма'!F60 -> select
B28: ='Form Форма'!F62 -> select
B29: ='Form Форма'!F64 -> select
B30: ='Form Форма'!F66 -> select
B31: ='Form Форма'!F68 -> select
B32: ='Form Форма'!F72 -> select
B33: ='Form Форма'!F74 -> select
B34: ='Form Форма'!F76 -> select
B37: ='Form Форма'!I10 -> 0
B38: ='Form Форма'!I12 -> 0
B39: ='Form Форма'!I14 -> 0
B40: ='Form Форма'!I16 -> 0
B41: ='Form Форма'!I18 -> 0
B42: ='Form Форма'!I20 -> 0
B43: ='Form Форма'!I22 -> 0
...
